Workbook

Sheet Master
A1: No | B1: Email | C1: Full name | D1: Người nhà | E1: Bus | F1: Room | G1: Gender | H1: Room Type
A2: 1 | B2: phamkhanh.tran@amaris.com | C2: =_xlfn.XLOOKUP(OfficeForms.Table[[#This Row],[Email]],Table2[Email],Table2[FullName],"") -> TRAN Pham Khanh Linh | E2: 1 | F2: 45 | G2: =IFERROR(_xlfn.XLOOKUP(OfficeForms.Table[[#This Row],[Email]],EE!C:C,EE!H:H,"Missing"),"Missing") -> Female | H2: DBL
A3: 2 | B3: thuytien.phamdo@amaris.com | C3: =_xlfn.XLOOKUP(OfficeForms.Table[[#This Row],[Email]],Table2[Email],Table2[FullName],"") -> PHAM Do Thuy Tien | E3: 1 | F3: 1 | G3: =IFERROR(_xlfn.XLOOKUP(OfficeForms.Table[[#This Row],[Email]],EE!C:C,EE!H:H,"Missing"),"Missing") -> Female | H3: DBL
A4: 3 | B4: hoangha.nguyen@amaris.com | C4: =_xlfn.XLOOKUP(OfficeForms.Table[[#This Row],[Email]],Table2[Email],Table2[FullName],"") -> NGUYEN Hoang Ha Quyen | E4: 1 | F4: 2 | G4: =IFERROR(_xlfn.XLOOKUP(OfficeForms.Table[[#This Row],[Email]],EE!C:C,EE!H:H,"Missing"),"Missing") -> Female | H4: DBL
A5: 4 | B5: thientrang.doan@amaris.com | C5: =_xlfn.XLOOKUP(OfficeForms.Table[[#This Row],[Email]],Table2[Email],Table2[FullName],"") -> DOAN Thien Trang | E5: 1 | F5: 2 | G5: =IFERROR(_xlfn.XLOOKUP(OfficeForms.Table[[#This Row],[Email]],EE!C:C,EE!H:H,"Missing"),"Missing") -> Female | H5: DBL
A6: 5 | B6: uhonguyenhong@amaris.com | C6: =_xlfn.XLOOKUP(OfficeForms.Table[[#This Row],[Email]],Table2[Email],Table2[FullName],"") -> HO Nguyen Hong Uyen | E6: 1 | F6: 85 | G6: =IFERROR(_xlfn.XLOOKUP(OfficeForms.Table[[#This Row],[Email]],EE!C:C,EE!H:H,"Missing"),"Missing") -> Female | H6: DBL
A7: 6 | B7: pha1@amaris.com | C7: =_xlfn.XLOOKUP(OfficeForms.Table[[#This Row],[Email]],Table2[Email],Table2[FullName],"") -> HA Phuong Thao | E7: 1 | F7: 88 | G7: =IFERROR(_xlfn.XLOOKUP(OfficeForms.Table[[#This Row],[Email]],EE!C:C,EE!H:H,"Missing"),"Missing") -> Female | H7: DBL
A8: 7 | B8: hvu3@amaris.com | C8: =_xlfn.XLOOKUP(OfficeForms.Table[[#This Row],[Email]],Table2[Email],Table2[FullName],"") -> VU Thanh Hang | E8: 1 | F8: 85 | G8: =IFERROR(_xlfn.XLOOKUP(OfficeForms.Table[[#This Row],[Email]],EE!C:C,EE!H:H,"Missing"),"Missing") -> Female | H8: DBL
A9: 8 | B9: cao.minh@amaris.com | C9: =_xlfn.XLOOKUP(OfficeForms.Table[[#This Row],[Email]],Table2[Email],Table2[FullName],"") -> CAO Duc Minh | E9: 1 | F9: 4 | G9: =IFERROR(_xlfn.XLOOKUP(OfficeForms.Table[[#This Row],[Email]],EE!C:C,EE!H:H,"Missing"),"Missing") -> Male | H9: TWN
A10: 9 | B10: hoangtu.la@amaris.com | C10: =_xlfn.XLOOKUP(OfficeForms.Table[[#This Row],[Email]],Table2[Email],Table2[FullName],"") -> LA Hoang Tu | E10: 1 | F10: 4 | G10: =IFERROR(_xlfn.XLOOKUP(OfficeForms.Table[[#This Row],[Email]],EE!C:C,EE!H:H,"Missing"),"Missing") -> Male | H10: TWN
A11: 10 | B11: trungnghia.cao@amaris.com | C11: =_xlfn.XLOOKUP(OfficeForms.Table[[#This Row],[Email]],Table2[Email],Table2[FullName],"") -> CAO Trung Nghia | E11: 1 | F11: 5 | G11: =IFERROR(_xlfn.XLOOKUP(OfficeForms.Table[[#This Row],[Email]],EE!C:C,EE!H:H,"Missing"),"Missing") -> Male | H11: TWN
A12: 11 | B12: minhthuan.le@amaris.com | C12: =_xlfn.XLOOKUP(OfficeForms.Table[[#This Row],[Email]],Table2[Email],Table2[FullName],"") -> LE Minh Thuan | E12: 1 | F12: 3 | G12: =IFERROR(_xlfn.XLOOKUP(OfficeForms.Table[[#This Row],[Email]],EE!C:C,EE!H:H,"Missing"),"Missing") -> Male | H12: TWN
A13: 12 | B13: thanhthuan.nguyenvan@amaris.com | C13: =_xlfn.XLOOKUP(OfficeForms.Table[[#This Row],[Email]],Table2[Email],Table2[FullName],"") -> NGUYEN Van Thanh Thuan | E13: 1 | F13: 3 | G13: =IFERROR(_xlfn.XLOOKUP(OfficeForms.Table[[#This Row],[Email]],EE!C:C,EE!H:H,"Missing"),"Missing") -> Male | H13: TWN
... A30: 29 | B30: thanhson.nguyen@amaris.com | C30: =_xlfn.XLOOKUP(OfficeForms.Table[[#This Row],[Email]],Table2[Email],Table2[FullName],"") -> NGUYEN Thanh Son | E30: 1 | F30: 10 | G30: =IFERROR(_xlfn.XLOOKUP(OfficeForms.Table[[#This Row],[Email]],EE!C:C,EE!H:H,"Missing"),"Missing") -> Male | H30: TWN
A31: 30 | B31: nguyen.tai3@amaris.com | C31: =_xlfn.XLOOKUP(OfficeForms.Table[[#This Row],[Email]],Table2[Email],Table2[FullName],"") -> NGUYEN Thanh Tai | D31: 1. Nguyen Thu Huyen - Female - 1991 - TBD 2. Nguyen Kha Han - Female - 2017 - TBD | E31: 1 | F31: 73 | G31: =IFERROR(_xlfn.XLOOKUP(OfficeForms.Table[[#This Row],[Email]],EE!C:C,EE!H:H,"Missing"),"Missing") -> Male | H31: DBL
A32: 31 | B32: vanthanh.khuat@amaris.com | C32: =_xlfn.XLOOKUP(OfficeForms.Table[[#This Row],[Email]],Table2[Email],Table2[FullName],"") -> KHUAT Van Thanh Danh | E32: 1 | F32: 12 | G32: =IFERROR(_xlfn.XLOOKUP(OfficeForms.Table[[#This Row],[Email]],EE!C:C,EE!H:H,"Missing"),"Missing") -> Male | H32: TWN
A33: 32 | B33: quangnien.nguyen@amaris.com | C33: =_xlfn.XLOOKUP(OfficeForms.Table[[#This Row],[Email]],Table2[Email],Table2[FullName],"") -> NGUYEN Quang Nien | E33: 1 | F33: 15 | G33: =IFERROR(_xlfn.XLOOKUP(OfficeForms.Table[[#This Row],[Email]],EE!C:C,EE!H:H,"Missing"),"Missing") -> Male | H33: TWN
A34: 33 | B34: thanhphuoc.le@amaris.com | C34: =_xlfn.XLOOKUP(OfficeForms.Table[[#This Row],[Email]],Table2[Email],Table2[FullName],"") -> LE Thanh Phuoc | E34: 1 | F34: 11 | G34: =IFERROR(_xlfn.XLOOKUP(OfficeForms.Table[[#This Row],[Email]],EE!C:C,EE!H:H,"Missing"),"Missing") -> Male | H34: TWN
A35: 34 | B35: nnguyen9@amaris.com | C35: =_xlfn.XLOOKUP(OfficeForms.Table[[#This Row],[Email]],Table2[Email],Table2[FullName],"") -> NGUYEN Tien Nam | E35: 8 | F35: 110 | G35: =IFERROR(_xlfn.XLOOKUP(OfficeForms.Table[[#This Row],[Email]],EE!C:C,EE!H:H,"Missing"),"Missing") -> Male | H35: TWN
A36: 35 | B36: congdanh.bui@amaris.com | C36: =_xlfn.XLOOKUP(OfficeForms.Table[[#This Row],[Email]],Table2[Email],Table2[FullName],"") -> BUI Cong Danh | E36: 1 | F36: 15 | G36: =IFERROR(_xlfn.XLOOKUP(OfficeForms.Table[[#This Row],[Email]],EE!C:C,EE!H:H,"Missing"),"Missing") -> Male | H36: TWN
A37: 36 | B37: huynhchi.vo@amaris.com | C37: =_xlfn.XLOOKUP(OfficeForms.Table[[#This Row],[Email]],Table2[Email],Table2[FullName],"") -> VO Huynh Chi Tin | E37: 1 | F37: 16 | G37: =IFERROR(_xlfn.XLOOKUP(OfficeForms.Table[[#This Row],[Email]],EE!C:C,EE!H:H,"Missing"),"Missing") -> Male | H37: TWN
A38: 37 | B38: quangtrung.do@amaris.com | C38: =_xlfn.XLOOKUP(OfficeForms.Table[[#This Row],[Email]],Table2[Email],Table2[FullName],"") -> DO Quang Trung | E38: 1 | F38: 16 | G38: =IFERROR(_xlfn.XLOOKUP(OfficeForms.Table[[#This Row],[Email]],EE!C:C,EE!H:H,"Missing"),"Missing") -> Male | H38: TWN
A39: 38 | B39: vantrien.dang@amaris.com | C39: =_xlfn.XLOOKUP(OfficeForms.Table[[#This Row],[Email]],Table2[Email],Table2[FullName],"") -> DANG Van Trien | E39: 2 | F39: 65 | G39: =IFERROR(_xlfn.XLOOKUP(OfficeForms.Table[[#This Row],[Email]],EE!C:C,EE!H:H,"Missing"),"Missing") -> Male | H39: TWN
A40: 39 | B40: thanhdat.nguyen@amaris.com | C40: =_xlfn.XLOOKUP(OfficeForms.Table[[#This Row],[Email]],Table2[Email],Table2[FullName],"") -> NGUYEN Thanh Dat | E40: 2 | F40: 66 | G40: =IFERROR(_xlfn.XLOOKUP(OfficeForms.Table[[#This Row],[Email]],EE!C:C,EE!H:H,"Missing"),"Missing") -> Male | H40: TWN
A41: 40 | B41: songtoan.vu@amaris.com | C41: =_xlfn.XLOOKUP(OfficeForms.Table[[#This Row],[Email]],Table2[Email],Table2[FullName],"") -> VU Song Toan | E41: 2 | F41: 66 | G41: =IFERROR(_xlfn.XLOOKUP(OfficeForms.Table[[#This Row],[Email]],EE!C:C,EE!H:H,"Missing"),"Missing") -> Male | H41: TWN
A42: 41 | B42: quangtin.tran@amaris.com | C42: =_xlfn.XLOOKUP(OfficeForms.Table[[#This Row],[Email]],Table2[Email],Table2[FullName],"") -> TRAN Quang Tin | E42: 2 | F42: 67 | G42: =IFERROR(_xlfn.XLOOKUP(OfficeForms.Table[[#This Row],[Email]],EE!C:C,EE!H:H,"Missing"),"Missing") -> Male | H42: TWN
A43: 42 | B43: tuongduy.vo@amaris.com | C43: =_xlfn.XLOOKUP(OfficeForms.Table[[#This Row],[Email]],Table2[Email],Table2[FullName],"") -> VO Tuong Duy | E43: 2 | F43: 67 | G43: =IFERROR(_xlfn.XLOOKUP(OfficeForms.Table[[#This Row],[Email]],EE!C:C,EE!H:H,"Missing"),"Missing") -> Male | H43: TWN
... A91: 90 | B91: minhtan.tran1@amaris.com | C91: =_xlfn.XLOOKUP(OfficeForms.Table[[#This Row],[Email]],Table2[Email],Table2[FullName],"") -> TRAN Minh Tan | E91: 3 | F91: 40 | G91: =IFERROR(_xlfn.XLOOKUP(OfficeForms.Table[[#This Row],[Email]],EE!C:C,EE!H:H,"Missing"),"Missing") -> Male | H91: TWN
A92: 91 | B92: nguyen.tuananh@amaris.com | C92: =_xlfn.XLOOKUP(OfficeForms.Table[[#This Row],[Email]],Table2[Email],Table2[FullName],"") -> NGUYEN Anh Tuan - Tl | D92: 1. TRẦN THỊ KIM THUỶ - 07/10/1998 - 079198004873 2. NGUYỄN NGỌC KIM ANH - 04/09/2022 - 079322018996 3. NGUYỄN NGỌC TUỆ NHI - 01/03/2024 - 079324006070 | E92: 3 | F92: 74 | G92: =IFERROR(_xlfn.XLOOKUP(OfficeForms.Table[[#This Row],[Email]],EE!C:C,EE!H:H,"Missing"),"Missing") -> Male | H92: TWN
A93: 92 | B93: nhamquy.tran@amaris.com | C93: =_xlfn.XLOOKUP(OfficeForms.Table[[#This Row],[Email]],Table2[Email],Table2[FullName],"") -> TRAN Nham Quy | D93: Lam Vi Phuong - Female - 25/05/1994 - 084194007540 | E93: 3 | F93: 72 | G93: =IFERROR(_xlfn.XLOOKUP(OfficeForms.Table[[#This Row],[Email]],EE!C:C,EE!H:H,"Missing"),"Missing") -> Male | H93: DBL
A94: 93 | B94: thuong.trinhxuan@amaris.com | C94: =_xlfn.XLOOKUP(OfficeForms.Table[[#This Row],[Email]],Table2[Email],Table2[FullName],"") -> TRINH Xuan Thuong | E94: 4 | F94: 57 | G94: =IFERROR(_xlfn.XLOOKUP(OfficeForms.Table[[#This Row],[Email]],EE!C:C,EE!H:H,"Missing"),"Missing") -> Male | H94: TWN
A95: 94 | B95: nguyen.huyhoang@amaris.com | C95: =_xlfn.XLOOKUP(OfficeForms.Table[[#This Row],[Email]],Table2[Email],Table2[FullName],"") -> NGUYEN Huy Hoang | D95: 1. Lương Thị Lưu - Female - 06/03/1993 - 040193036578 2. Nguyễn Lương Hoàng Yến - Female - 19/10/2021 - 086321006062 3. Nguyễn Lương Thanh Thảo - Female - 06/03/2024 - 086324001119 | E95: 3 | F95: 75 | G95: =IFERROR(_xlfn.XLOOKUP(OfficeForms.Table[[#This Row],[Email]],EE!C:C,EE!H:H,"Missing"),"Missing") -> Male | H95: TWN
A96: 95 | B96: vanhieu.nguyen@amaris.com | C96: =_xlfn.XLOOKUP(OfficeForms.Table[[#This Row],[Email]],Table2[Email],Table2[FullName],"") -> NGUYEN Van Hieu | E96: 3 | F96: 41 | G96: =IFERROR(_xlfn.XLOOKUP(OfficeForms.Table[[#This Row],[Email]],EE!C:C,EE!H:H,"Missing"),"Missing") -> Male | H96: TWN
A97: 96 | B97: kimgia.nguyen@amaris.com | C97: =_xlfn.XLOOKUP(OfficeForms.Table[[#This Row],[Email]],Table2[Email],Table2[FullName],"") -> NGUYEN Kim Gia Huy | E97: 3 | F97: 41 | G97: =IFERROR(_xlfn.XLOOKUP(OfficeForms.Table[[#This Row],[Email]],EE!C:C,EE!H:H,"Missing"),"Missing") -> Male | H97: TWN
A98: 97 | B98: congquan.pham@amaris.com | C98: =_xlfn.XLOOKUP(OfficeForms.Table[[#This Row],[Email]],Table2[Email],Table2[FullName],"") -> PHAM Cong Quan | D98: 1. Ung Thụy Song Quỳnh - Female - 11/11/1995 - 049195000151 2. Phạm Công Quang - Male - 26/05/2024 - 049224004390 | E98: 3 | F98: 76 | G98: =IFERROR(_xlfn.XLOOKUP(OfficeForms.Table[[#This Row],[Email]],EE!C:C,EE!H:H,"Missing"),"Missing") -> Male | H98: DBL
A99: 98 | B99: thanhxuan.bui@amaris.com | C99: =_xlfn.XLOOKUP(OfficeForms.Table[[#This Row],[Email]],Table2[Email],Table2[FullName],"") -> BUI Thanh Xuan | E99: 3 | F99: 42 | G99: =IFERROR(_xlfn.XLOOKUP(OfficeForms.Table[[#This Row],[Email]],EE!C:C,EE!H:H,"Missing"),"Missing") -> Male | H99: TWN
A100: 99 | B100: thiphuong.vu@amaris.com | C100: =_xlfn.XLOOKUP(OfficeForms.Table[[#This Row],[Email]],Table2[Email],Table2[FullName],"") -> VU Thi Phuong Thao | D100: Cao Thi Truc Duyen - Female - 15/06/1997 - 083197002767 | E100: 3 | F100: 43 | G100: =IFERROR(_xlfn.XLOOKUP(OfficeForms.Table[[#This Row],[Email]],EE!C:C,EE!H:H,"Missing"),"Missing") -> Female | H100: DBL
A101: 100 | B101: vantinh.pham@amaris.com | C101: =_xlfn.XLOOKUP(OfficeForms.Table[[#This Row],[Email]],Table2[Email],Table2[FullName],"") -> PHAM Van Tinh | E101: 3 | F101: 42 | G101: =IFERROR(_xlfn.XLOOKUP(OfficeForms.Table[[#This Row],[Email]],EE!C:C,EE!H:H,"Missing"),"Missing") -> Male | H101: TWN
A102: 101 | B102: tuan.vancong@amaris.com | C102: =_xlfn.XLOOKUP(OfficeForms.Table[[#This Row],[Email]],Table2[Email],Table2[FullName],"") -> VAN Cong Tuan | D102: Nguyen Thi Viet Le - Female - 20/11/1997 - 049197010026 | E102: 3 | F102: 71 | G102: =IFERROR(_xlfn.XLOOKUP(OfficeForms.Table[[#This Row],[Email]],EE!C:C,EE!H:H,"Missing"),"Missing") -> Male | H102: DBL
A103: 102 | B103: thanhtrung.nguyen@amaris.com | C103: =_xlfn.XLOOKUP(OfficeForms.Table[[#This Row],[Email]],Table2[Email],Table2[FullName],"") -> NGUYEN Thanh Trung | E103: 4 | F103: 46 | G103: =IFERROR(_xlfn.XLOOKUP(OfficeForms.Table[[#This Row],[Email]],EE!C:C,EE!H:H,"Missing"),"Missing") -> Male | H103: TWN
...

Sheet Bus leader
A1: Bus No | B1: Leader Mail | C1: Leader Name | D1: Leader Phone
A2: 1 | B2: congdanh.bui@amaris.com | C2: Cong Danh BUI | D2: 0902891404
A3: 2 | B3: hla@amaris.com | C3: Thuy My Hao LA | D3: 0375225989
A4: 3 | B4: vanhieu.nguyen@amaris.com | C4: Van Hieu NGUYEN | D4: 0397459642
A5: 4 | B5: pnguyen4@amaris.com | C5: Thi Minh Phuong NGUYEN | D5: 0945745944 | K5: thanhson.nguyen@amaris.com | L5: NGUYEN Thanh Son | M5: 0392497315
A6: 5 | B6: knguyen8@mantu.com | C6: Trung Kien NGUYEN | D6: 0355327017
A7: 6 | B7: tngo@mantu.com | C7: NGO Trinh Quynh Nhu | D7: 0886311686
A8: 7 | B8: tran.ngocquoc@amaris.com | C8: Ngoc Quoc TRAN | D8: 0799010869
A9: 8 | B9: bhoang@mantu.com | C9: HOANG Bao An | D9: 0339526385

Sheet Room
A1: Name | B1: Are you planning to join the company trip? | C1: Please enter your ID/Passport number. | D1: Please enter your phone number (just in case we need to get in touch) | E1: Are you bringing any partner or family members along? | F1: If yes, please provide the details for each guest below | G1: How do you plan to travel to the trip location? | H1: Anything else we should know? | I1: Gov | J1: Dep | K1: N+1 | L1: Status | M1: With Fam | N1: C Fam | O1: A Fam | P1: Fam Q | Q1: Total Hc | R1: Bus No. | S1: Room No. | T1: Gender | AA1: Are you planning to join the company trip? | AB1: (All) | AI1: Are you planning to join the company trip? | AJ1: (All)
A2: Pham Khanh Linh TRAN | B2: Yes, count me in! | C2: 044199002375 | D2: 0823387274 | E2: No | G2: I’ll take the company bus | I2: Amaris Consulting | J2: Consultants | K2: HA Phuong Thao | L2: In | M2: No | N2: 0 | O2: 0 | P2: 0 | Q2: 1 | R2: 1 | S2: 1 | T2: =_xlfn.XLOOKUP(A2,Master!#REF!,Master!G:G) -> #REF!
A3: Do Thuy Tien PHAM | B3: Yes, count me in! | C3: 070194001945 | D3: 0396744435 | E3: No | G3: I’ll take the company bus | I3: Amaris Consulting | J3: Consultants | K3: HO Nguyen Hong Uyen | L3: In | M3: No | N3: 0 | O3: 0 | P3: 0 | Q3: 1 | R3: 1 | S3: 1 | T3: =_xlfn.XLOOKUP(A3,Master!#REF!,Master!G:G) -> #REF! | W3: {=_xlfn.UNIQUE(S2:S272)} -> 1 | AA3: Bus No. | AB3: Room No. | AC3: Name | AD3: Sum of Fam Q | AE3: Sum of Total Hc | AI3: Gender | AJ3: Room No. | AK3: With Fam | AL3: Bus No. | AM3: Name | AN3: Sum of Fam Q | AO3: Sum of Total Hc
A4: Hoang Ha Quyen NGUYEN | B4: Yes, count me in! | C4: 077300001719 | D4: 0968963049 | E4: No | G4: I’ll take the company bus | I4: Amaris Consulting | J4: Consultants | K4: HO Nguyen Hong Uyen | L4: In | M4: No | N4: 0 | O4: 0 | P4: 0 | Q4: 1 | R4: 1 | S4: 2 | T4: =_xlfn.XLOOKUP(A4,Master!#REF!,Master!G:G) -> #REF! | W4: 2 | AA4: 1 | AB4: 1 | AC4: Do Thuy Tien PHAM | AD4: 0 | AE4: 1 | AI4: Female | AJ4: 1 | AN4: 0 | AO4: 2 | AP4: =AO4 -> 2
A5: Thien Trang DOAN | B5: Yes, count me in! | C5: 091300011455 | D5: 0918626459 | E5: No | G5: I’ll take the company bus | H5: If there’s a single room, I wanna stay alone (if any) | I5: Amaris Consulting | J5: Consultants | K5: HO Nguyen Hong Uyen | L5: In | M5: No | N5: 0 | O5: 0 | P5: 0 | Q5: 1 | R5: 1 | S5: 2 | T5: =_xlfn.XLOOKUP(A5,Master!#REF!,Master!G:G) -> #REF! | W5: 3 | AA5: 1 | AB5: 1 | AC5: Pham Khanh Linh TRAN | AD5: 0 | AE5: 1 | AI5: Female | AJ5: 2 | AN5: 0 | AO5: 2 | AP5: =AO5 -> 2
A6: Minh Thuan LE | B6: Yes, count me in! | C6: 086099002987 | D6: 0968933873 | E6: No | G6: I’ll take the company bus | I6: Amaris Consulting | J6: Consultants | K6: HA Phuong Thao | L6: In | M6: No | N6: 0 | O6: 0 | P6: 0 | Q6: 1 | R6: 1 | S6: 3 | T6: =_xlfn.XLOOKUP(A6,Master!#REF!,Master!G:G) -> #REF! | W6: 4 | AA6: 1 | AB6: 2 | AC6: Hoang Ha Quyen NGUYEN | AD6: 0 | AE6: 1 | AI6: Female | AJ6: 31 | AN6: 0 | AO6: 2 | AP6: =AO6 -> 2
A7: Van Thanh Thuan NGUYEN | B7: Yes, count me in! | C7: 080095004933 | D7: 0793485644 | E7: No | G7: I’ll take the company bus | H7: I'd like to request to be booked in the same room as the IVB team. | I7: Amaris Consulting | J7: Consultants | K7: HA Phuong Thao | L7: In | M7: No | N7: 0 | O7: 0 | P7: 0 | Q7: 1 | R7: 1 | S7: 3 | T7: =_xlfn.XLOOKUP(A7,Master!#REF!,Master!G:G) -> #REF! | W7: 5 | AA7: 1 | AB7: 2 | AC7: Thien Trang DOAN | AD7: 0 | AE7: 1 | AI7: Female | AJ7: 32 | AN7: 0 | AO7: 2 | AP7: =AO7 -> 2
A8: Duc Minh CAO | B8: Yes, count me in! | C8: 080202010719 | D8: 0942198738 | E8: No | G8: I’ll take the company bus | I8: Amaris Consulting | J8: Consultants | K8: HA Phuong Thao | L8: In | M8: No | N8: 0 | O8: 0 | P8: 0 | Q8: 1 | R8: 1 | S8: 4 | T8: =_xlfn.XLOOKUP(A8,Master!#REF!,Master!G:G) -> #REF! | W8: 6 | AA8: 1 | AB8: 4 | AC8: Duc Minh CAO | AD8: 0 | AE8: 1 | AI8: Female | AJ8: 33 | AN8: 0 | AO8: 2 | AP8: =AO8 -> 2
A9: Hoang Tu LA | B9: Yes, count me in! | C9: 083097005277 | D9: 0386788883 | E9: No | G9: I’ll take the company bus | I9: Amaris Consulting | J9: Consultants | K9: HA Phuong Thao | L9: In | M9: No | N9: 0 | O9: 0 | P9: 0 | Q9: 1 | R9: 1 | S9: 4 | T9: =_xlfn.XLOOKUP(A9,Master!#REF!,Master!G:G) -> #REF! | W9: 7 | AA9: 1 | AB9: 4 | AC9: Hoang Tu LA | AD9: 0 | AE9: 1 | AI9: Female | AJ9: 34 | AN9: 0 | AO9: 2 | AP9: =AO9 -> 2
A10: Trung Nghia CAO | B10: Yes, count me in! | C10: 051094000961 | D10: 0938945445 | E10: No | G10: I’ll take the company bus | I10: Amaris Consulting | J10: Consultants | K10: HA Phuong Thao | L10: In | M10: No | N10: 0 | O10: 0 | P10: 0 | Q10: 1 | R10: 1 | S10: 5 | T10: =_xlfn.XLOOKUP(A10,Master!#REF!,Master!G:G) -> #REF! | W10: 8 | AA10: 1 | AB10: 5 | AC10: Trung Nghia CAO | AD10: 0 | AE10: 1 | AI10: Female | AJ10: 44 | AN10: 0 | AO10: 2 | AP10: =AO10 -> 2
A11: Van Do TRAN | B11: Yes, count me in! | C11: 089097020361 | D11: 0967513840 | E11: No | G11: I’ll take the company bus | I11: Amaris Consulting | J11: Consultants | K11: HA Phuong Thao | L11: In | M11: No | N11: 0 | O11: 0 | P11: 0 | Q11: 1 | R11: 1 | S11: 5 | T11: =_xlfn.XLOOKUP(A11,Master!#REF!,Master!G:G) -> #REF! | W11: 9 | AA11: 1 | AB11: 5 | AC11: Van Do TRAN | AD11: 0 | AE11: 1 | AI11: Female | AJ11: 45 | AN11: 0 | AO11: 2 | AP11: =AO11 -> 2
A12: Quang Trinh HA | B12: Yes, count me in! | C12: 087099016549 | D12: 0826759579 | E12: No | G12: I’ll take the company bus | I12: Amaris Consulting | J12: Consultants | K12: HA Phuong Thao | L12: In | M12: No | N12: 0 | O12: 0 | P12: 0 | Q12: 1 | R12: 1 | S12: 6 | T12: =_xlfn.XLOOKUP(A12,Master!#REF!,Master!G:G) -> #REF! | W12: 10 | AA12: 1 | AB12: 6 | AC12: Binh Nam MAI | AD12: 0 | AE12: 1 | AI12: Female | AJ12: 60 | AN12: 0 | AO12: 2 | AP12: =AO12 -> 2
A13: Binh Nam MAI | B13: Yes, count me in! | C13: 044099000541 | D13: 0948527910 | E13: No | G13: I’ll take the company bus | I13: Amaris Consulting | J13: Consultants | K13: HA Phuong Thao | L13: In | M13: No | N13: 0 | O13: 0 | P13: 0 | Q13: 1 | R13: 1 | S13: 6 | T13: =_xlfn.XLOOKUP(A13,Master!#REF!,Master!G:G) -> #REF! | W13: 11 | AA13: 1 | AB13: 6 | AC13: Quang Trinh HA | AD13: 0 | AE13: 1 | AI13: Female | AJ13: 61 | AN13: 0 | AO13: 2 | AP13: =AO13 -> 2
A14: Ngô Tấn Thành | B14: Yes, count me in! | C14: 089200015516 | D14: +84 329 382 782 | E14: No | G14: I’ll take the company bus | H14: Team chị My | I14: Amaris Consulting | J14: Consultants | K14: HA Phuong Thao | L14: In | M14: No | N14: 0 | O14: 0 | P14: 0 | Q14: 1 | R14: 1 | S14: 7 | T14: =_xlfn.XLOOKUP(A14,Master!#REF!,Master!G:G) -> #REF! | W14: 12 | AA14: 1 | AB14: 7 | AC14: Hong Chuong NGUYEN | AD14: 0 | AE14: 1 | AI14: Female | AJ14: 62 | AN14: 0 | AO14: 2 | AP14: =AO14 -> 2
A15: Hong Chuong NGUYEN | B15: Yes, count me in! | C15: 083084008265 | D15: 0989600669 | E15: No | G15: I’ll take the company bus | I15: Amaris Consulting | J15: Consultants | K15: HA Phuong Thao | L15: In | M15: No | N15: 0 | O15: 0 | P15: 0 | Q15: 1 | R15: 1 | S15: 7 | T15: =_xlfn.XLOOKUP(A15,Master!#REF!,Master!G:G) -> #REF! | W15: 13 | AA15: 1 | AB15: 7 | AC15: Ngô Tấn Thành | AD15: 0 | AE15: 1 | AI15: Female | AJ15: 68 | AN15: 0 | AO15: 1 | AP15: =AO15 -> 1
A16: Nguyễn Lê Thành | B16: Yes, count me in! | C16: 062201003205 | D16: +84 931 182 688 | E16: No | G16: I’ll take the company bus | I16: Amaris Consulting | J16: Consultants | K16: HA Phuong Thao | L16: In | M16: No | N16: 0 | O16: 0 | P16: 0 | Q16: 1 | R16: 1 | S16: 8 | T16: =_xlfn.XLOOKUP(A16,Master!#REF!,Master!G:G) -> #REF! | W16: 14 | AA16: 1 | AB16: 8 | AC16: Ngoc Tuan NGUYEN | AD16: 0 | AE16: 1 | AI16: Female | AJ16: 69 | AN16: 0 | AO16: 2 | AP16: =AO16 -> 2
A17: Ngoc Tuan NGUYEN | B17: Yes, count me in! | C17: 051099011537 | D17: 0973724249 | E17: No | G17: I’ll take the company bus | I17: Amaris Consulting | J17: Consultants | K17: HO Nguyen Hong Uyen | L17: In | M17: No | N17: 0 | O17: 0 | P17: 0 | Q17: 1 | R17: 1 | S17: 8 | T17: =_xlfn.XLOOKUP(A17,Master!#REF!,Master!G:G) -> #REF! | W17: 15 | AA17: 1 | AB17: 8 | AC17: Nguyễn Lê Thành | AD17: 0 | AE17: 1 | AI17: Female | AJ17: 82 | AN17: 0 | AO17: 2 | AP17: =AO17 -> 2
A18: Thanh Nhan PHAN | B18: Yes, count me in! | C18: 079096015213 | D18: 0392357076 | E18: No | G18: I’ll take the company bus | I18: Amaris Consulting | J18: Consultants | K18: HO Nguyen Hong Uyen | L18: In | M18: No | N18: 0 | O18: 0 | P18: 0 | Q18: 1 | R18: 1 | S18: 9 | T18: =_xlfn.XLOOKUP(A18,Master!#REF!,Master!G:G) -> #REF! | W18: 16 | AA18: 1 | AB18: 9 | AC18: Thanh Nhan PHAN | AD18: 0 | AE18: 1 | AI18: Female | AJ18: 83 | AN18: 0 | AO18: 2 | AP18: =AO18 -> 2
A19: Xuan Dat HOANG | B19: Yes, count me in! | C19: 066201016152 | D19: 0393688714 | E19: No | G19: I’ll take the company bus | I19: Amaris Consulting | J19: Consultants | K19: HO Nguyen Hong Uyen | L19: In | M19: No | N19: 0 | O19: 0 | P19: 0 | Q19: 1 | R19: 1 | S19: 9 | T19: =_xlfn.XLOOKUP(A19,Master!#REF!,Master!G:G) -> #REF! | W19: 17 | AA19: 1 | AB19: 9 | AC19: Xuan Dat HOANG | AD19: 0 | AE19: 1 | AI19: Female | AJ19: 84 | AN19: 0 | AO19: 2 | AP19: =AO19 -> 2
A20: Hong Son DAO | B20: Yes, count me in! | C20: 075200024308 | D20: 0938316793 | E20: No | G20: I’ll take the company bus | I20: Amaris Consulting | J20: Consultants | K20: HO Nguyen Hong Uyen | L20: In | M20: No | N20: 0 | O20: 0 | P20: 0 | Q20: 1 | R20: 1 | S20: 10 | T20: =_xlfn.XLOOKUP(A20,Master!#REF!,Master!G:G) -> #REF! | W20: 18 | AA20: 1 | AB20: 10 | AC20: Hong Son DAO | AD20: 0 | AE20: 1 | AI20: Female | AJ20: 85 | AN20: 0 | AO20: 2 | AP20: =AO20 -> 2
A21: Thanh Son NGUYEN | B21: Yes, count me in! | C21: 051098005098 | D21: 0392497315 | E21: No | G21: I’ll take the company bus | I21: Amaris Consulting | J21: Consultants | K21: HO Nguyen Hong Uyen | L21: In | M21: No | N21: 0 | O21: 0 | P21: 0 | Q21: 1 | R21: 1 | S21: 10 | T21: =_xlfn.XLOOKUP(A21,Master!#REF!,Master!G:G) -> #REF! | W21: 19 | AA21: 1 | AB21: 10 | AC21: Thanh Son NGUYEN | AD21: 0 | AE21: 1 | AI21: Female | AJ21: 86 | AN21: 0 | AO21: 2 | AP21: =AO21 -> 2
A22: Thanh Phuoc LE | B22: Yes, count me in! | C22: 068096007001 | D22: 0357556867 | E22: No | G22: I’ll take the company bus | I22: Amaris Consulting | J22: Consultants | K22: HO Nguyen Hong Uyen | L22: In | M22: No | N22: 0 | O22: 0 | P22: 0 | Q22: 1 | R22: 1 | S22: 11 | T22: =_xlfn.XLOOKUP(A22,Master!#REF!,Master!G:G) -> #REF! | W22: 20 | AA22: 1 | AB22: 11 | AC22: Le Man Dat NGUYEN | AD22: 0 | AE22: 1 | AI22: Female | AJ22: 87 | AN22: 0 | AO22: 2 | AP22: =AO22 -> 2
A23: Le Man Dat NGUYEN | B23: Yes, count me in! | C23: 086200001291 | D23: 0337804259 | E23: No | G23: I’ll take the company bus | I23: Amaris Consulting | J23: Consultants | K23: HO Nguyen Hong Uyen | L23: In | M23: No | N23: 0 | O23: 0 | P23: 0 | Q23: 1 | R23: 1 | S23: 11 | T23: =_xlfn.XLOOKUP(A23,Master!#REF!,Master!G:G) -> #REF! | W23: 21 | AA23: 1 | AB23: 11 | AC23: Thanh Phuoc LE | AD23: 0 | AE23: 1 | AI23: Female | AJ23: 88 | AN23: 0 | AO23: 2 | AP23: =AO23 -> 2
A24: Thanh Loc NGUYEN | B24: Yes, count me in! | C24: 046097000064 | D24: 0333515756 | E24: No | G24: I’ll take the company bus | I24: Amaris Consulting | J24: Consultants | K24: HO Nguyen Hong Uyen | L24: In | M24: No | N24: 0 | O24: 0 | P24: 0 | Q24: 1 | R24: 1 | S24: 12 | T24: =_xlfn.XLOOKUP(A24,Master!#REF!,Master!G:G) -> #REF! | W24: 22 | AA24: 1 | AB24: 12 | AC24: Thanh Loc NGUYEN | AD24: 0 | AE24: 1 | AI24: Female | AJ24: 89 | AN24: 0 | AO24: 2 | AP24: =AO24 -> 2
A25: Van Thanh Danh KHUAT | B25: Yes, count me in! | C25: 077203004018 | D25: 0971007831 | E25: No | G25: I’ll take the company bus | I25: Amaris Consulting | J25: Consultants | K25: HO Nguyen Hong Uyen | L25: In | M25: No | N25: 0 | O25: 0 | P25: 0 | Q25: 1 | R25: 1 | S25: 12 | T25: =_xlfn.XLOOKUP(A25,Master!#REF!,Master!G:G) -> #REF! | W25: 23 | AA25: 1 | AB25: 12 | AC25: Van Thanh Danh KHUAT | AD25: 0 | AE25: 1 | AI25: Female | AJ25: 94 | AN25: 0 | AO25: 2 | AP25: =AO25 -> 2
A26: Huu Vinh NGUYEN | B26: Yes, count me in! | C26: 089200019968 | D26: 0974086701 | E26: No | G26: I’ll take the company bus | I26: Amaris Consulting | J26: Consultants | K26: HO Nguyen Hong Uyen | L26: In | M26: No | N26: 0 | O26: 0 | P26: 0 | Q26: 1 | R26: 1 | S26: 13 | T26: =_xlfn.XLOOKUP(A26,Master!#REF!,Master!G:G) -> #REF! | W26: 24 | AA26: 1 | AB26: 13 | AC26: Huu Vinh NGUYEN | AD26: 0 | AE26: 1 | AI26: Female | AJ26: 95 | AN26: 0 | AO26: 2 | AP26: =AO26 -> 2
... A30: Quang Nien NGUYEN | B30: Yes, count me in! | C30: 058201000239 | D30: 0855586358 | E30: No | G30: I’ll take the company bus | I30: Amaris Consulting | J30: Consultants | K30: HO Nguyen Hong Uyen | L30: In | M30: No | N30: 0 | O30: 0 | P30: 0 | Q30: 1 | R30: 1 | S30: 15 | T30: =_xlfn.XLOOKUP(A30,Master!#REF!,Master!G:G) -> #REF! | W30: 28 | AA30: 1 | AB30: 15 | AC30: Cong Danh BUI | AD30: 0 | AE30: 1 | AI30: Female | AJ30: 99 | AN30: 0 | AO30: 2 | AP30: =AO30 -> 2
A31: Cong Danh BUI | B31: Yes, count me in! | C31: 079201014939 | D31: 0902891404 | E31: No | G31: I’ll take the company bus | H31: Motion sickness pills | I31: Amaris Consulting | J31: Consultants | K31: NGUYEN Tien Nam | L31: In | M31: No | N31: 0 | O31: 0 | P31: 0 | Q31: 1 | R31: 1 | S31: 15 | T31: =_xlfn.XLOOKUP(A31,Master!#REF!,Master!G:G) -> #REF! | W31: 29 | AA31: 1 | AB31: 15 | AC31: Quang Nien NGUYEN | AD31: 0 | AE31: 1 | AI31: Female | AJ31: 100 | AN31: 0 | AO31: 2 | AP31: =AO31 -> 2
A32: Huynh Chi Tin VO | B32: Yes, count me in! | C32: 079095022758 | D32: 0777104166 | E32: No | G32: I’ll take the company bus | I32: Amaris Consulting | J32: Consultants | K32: NGUYEN Tien Nam | L32: In | M32: No | N32: 0 | O32: 0 | P32: 0 | Q32: 1 | R32: 1 | S32: 16 | T32: =_xlfn.XLOOKUP(A32,Master!#REF!,Master!G:G) -> #REF! | W32: 30 | AA32: 1 | AB32: 16 | AC32: Huynh Chi Tin VO | AD32: 0 | AE32: 1 | AI32: Female | AJ32: 101 | AN32: 0 | AO32: 2 | AP32: =AO32 -> 2
A33: Quang Trung DO | B33: Yes, count me in! | C33: 064200012749 | D33: 0396402696 | E33: No | G33: I’ll take the company bus | I33: Amaris Consulting | J33: Consultants | K33: NGUYEN Tien Nam | L33: In | M33: No | N33: 0 | O33: 0 | P33: 0 | Q33: 1 | R33: 1 | S33: 16 | T33: =_xlfn.XLOOKUP(A33,Master!#REF!,Master!G:G) -> #REF! | W33: 31 | AA33: 1 | AB33: 16 | AC33: Quang Trung DO | AD33: 0 | AE33: 1 | AI33: Female | AJ33: 102 | AN33: 0 | AO33: 2 | AP33: =AO33 -> 2
A34: Van Trien DANG | B34: Yes, count me in! | C34: 068097008720 | D34: 0981212098 | E34: No | G34: I’ll take the company bus | I34: Amaris Consulting | J34: Consultants | K34: HOANG Thien | L34: In | M34: No | N34: 0 | O34: 0 | P34: 0 | Q34: 1 | R34: 7 | S34: 17 | T34: =_xlfn.XLOOKUP(A34,Master!#REF!,Master!G:G) -> #REF! | W34: 32 | AA34: 1 | AB34: 85 | AC34: Nguyen Hong Uyen HO | AD34: 0 | AE34: 1 | AI34: Female | AJ34: 103 | AN34: 0 | AO34: 2 | AP34: =AO34 -> 2
A35: Cong Khanh HUYNH | B35: Yes, count me in! | C35: 087201004021 | D35: 0777905219 | E35: No | G35: I’ll take the company bus | I35: Amaris Consulting | J35: Consultants | K35: HUYNH Chi Cuong | L35: In | M35: No | N35: 0 | O35: 0 | P35: 0 | Q35: 1 | R35: 2 | S35: 17 | T35: =_xlfn.XLOOKUP(A35,Master!#REF!,Master!G:G) -> #REF! | W35: 33 | AA35: 1 | AB35: 85 | AC35: Phuong Thao HA | AD35: 0 | AE35: 1 | AI35: Female | AJ35: 104 | AN35: 0 | AO35: 2 | AP35: =AO35 -> 2
A36: Thanh Dat NGUYEN | B36: Yes, count me in! | C36: 075096016711 | D36: 0932980033 | E36: No | G36: I’ll take the company bus | I36: Amaris Consulting | J36: Consultants | K36: HOANG Thien | L36: In | M36: No | N36: 0 | O36: 0 | P36: 0 | Q36: 1 | R36: 7 | S36: 18 | T36: =_xlfn.XLOOKUP(A36,Master!#REF!,Master!G:G) -> #REF! | W36: 34 | AA36: 1 | AB36: 86 | AC36: Thanh Hang VU | AD36: 0 | AE36: 1 | AI36: Female | AJ36: 116 | AN36: 0 | AO36: 2 | AP36: =AO36 -> 2
A37: Song Toan VU | B37: Yes, count me in! | C37: 048095001773 | D37: 0335353685 | E37: No | G37: I’ll take the company bus | I37: Amaris Consulting | J37: Consultants | K37: HOANG Thien | L37: In | M37: No | N37: 0 | O37: 0 | P37: 0 | Q37: 1 | R37: 7 | S37: 18 | T37: =_xlfn.XLOOKUP(A37,Master!#REF!,Master!G:G) -> #REF! | W37: 35 | AA37: 1 | AB37: 90 | AC37: NGUYEN Tien Nam | AD37: 0 | AE37: 1 | AI37: Female | AJ37: 117 | AN37: 0 | AO37: 2 | AP37: =AO37 -> 2
A38: Quang Tin TRAN | B38: Yes, count me in! | C38: 058095001270 | D38: 0349687204 | E38: No | G38: I’ll take the company bus | I38: Amaris Consulting | J38: Consultants | K38: HOANG Thien | L38: In | M38: No | N38: 0 | O38: 0 | P38: 0 | Q38: 1 | R38: 7 | S38: 19 | T38: =_xlfn.XLOOKUP(A38,Master!#REF!,Master!G:G) -> #REF! | W38: 36 | AA38: 1 | AB38: 3 | AC38: Minh Thuan LE | AD38: 0 | AE38: 1 | AI38: Female | AJ38: 118 | AN38: 0 | AO38: 2 | AP38: =AO38 -> 2
A39: Vo Tuong Duy | B39: Yes, count me in! | C39: 079200028676 | D39: 0397974403 | E39: No | G39: I’ll take the company bus | I39: Amaris Consulting | J39: Consultants | K39: HOANG Thien | L39: In (Exit confirmed) | M39: No | P39: 0 | Q39: 1 | R39: 7 | S39: 19 | T39: =_xlfn.XLOOKUP(A39,Master!#REF!,Master!G:G) -> #REF! | W39: 37 | AA39: 1 | AB39: 3 | AC39: Van Thanh Thuan NGUYEN | AD39: 0 | AE39: 1 | AI39: Female | AJ39: 119 | AN39: 0 | AO39: 2 | AP39: =AO39 -> 2
A40: Ngoc Thanh PHAM | B40: Yes, count me in! | C40: 060094011465 | D40: 0333950268 | E40: No | G40: I’ll take the company bus | I40: Amaris Consulting | J40: Consultants | K40: HUYNH Chi Cuong | L40: In | M40: No | N40: 0 | O40: 0 | P40: 0 | Q40: 1 | R40: 2 | S40: 20 | T40: =_xlfn.XLOOKUP(A40,Master!#REF!,Master!G:G) -> #REF! | W40: 38 | AA40: 1 | AB40: 73 | AC40: Thanh Tai NGUYEN | AD40: 2 | AE40: 3 | AI40: Female | AJ40: 122 | AN40: 0 | AO40: 2 | AP40: =AO40 -> 2
A41: Xuan Vu TRAN | B41: Yes, count me in! | C41: 046098001181 | D41: 0327360123 | E41: No | G41: I’ll take the company bus | I41: Amaris Consulting | J41: Consultants | K41: HUYNH Chi Cuong | L41: In | M41: No | N41: 0 | O41: 0 | P41: 0 | Q41: 1 | R41: 2 | S41: 20 | T41: =_xlfn.XLOOKUP(A41,Master!#REF!,Master!G:G) -> #REF! | W41: 39 | AA41: 1 Total | AD41: 2 | AE41: 39 | AI41: Female | AJ41: 123 | AN41: 0 | AO41: 3 | AP41: =AO41 -> 3
A42: Nhu Hai Luu PHAN | B42: Yes, count me in! | C42: 060099011492 | D42: 0379738098 | E42: No | G42: I’ll take the company bus | I42: Amaris Consulting | J42: Consultants | K42: LA Thuy My Hao | L42: In | M42: No | N42: 0 | O42: 0 | P42: 0 | Q42: 1 | R42: 2 | S42: 21 | T42: =_xlfn.XLOOKUP(A42,Master!#REF!,Master!G:G) -> #REF! | W42: 40 | AA42: 2 | AB42: 17 | AC42: Cong Khanh HUYNH | AD42: 0 | AE42: 1 | AI42: Female | AJ42: 124 | AN42: 0 | AO42: 2 | AP42: =AO42 -> 2
A43: Hoai Sang CAO | B43: Yes, count me in! | C43: 095203009143 | D43: 0944552050 | E43: No | G43: I’ll take the company bus | I43: Amaris Consulting | J43: Consultants | K43: LA Thuy My Hao | L43: In | M43: No | N43: 0 | O43: 0 | P43: 0 | Q43: 1 | R43: 2 | S43: 21 | T43: =_xlfn.XLOOKUP(A43,Master!#REF!,Master!G:G) -> #REF! | W43: 57 | AA43: 2 | AB43: 17 | AC43: Van Trien DANG | AD43: 0 | AE43: 1 | AI43: Female | AJ43: 125 | AN43: 0 | AO43: 2 | AP43: =AO43 -> 2
...

Sheet Update
A1: Name | B1: Are you planning to join the company trip? | C1: Please enter your ID/Passport number. | D1: Please enter your phone number (just in case we need to get in touch) | E1: Are you bringing any partner or family members along? | F1: If yes, please provide the details for each guest below | G1: How do you plan to travel to the trip location? | H1: Anything else we should know? | I1: Gov | J1: Dep | K1: N+1 | L1: Status | M1: With Fam | N1: C Fam | O1: A Fam | P1: Fam Q | Q1: Total Hc | R1: Bus No. | S1: Room No. | Y1: With Fam | Z1: No
A2: Pham Khanh Linh TRAN | B2: Yes, count me in! | C2: 044199002375 | D2: 0823387274 | E2: No | G2: I’ll take the company bus | I2: Amaris Consulting | J2: Consultants | K2: HA Phuong Thao | L2: In | M2: No | N2: 0 | O2: 0 | P2: 0 | Q2: 1 | R2: 3 | S2: 45
A3: Do Thuy Tien PHAM | B3: Yes, count me in! | C3: 070194001945 | D3: 0396744435 | E3: No | G3: I’ll take the company bus | I3: Amaris Consulting | J3: Consultants | K3: HO Nguyen Hong Uyen | L3: In | M3: No | N3: 0 | O3: 0 | P3: 0 | Q3: 1 | R3: 1 | S3: 1 | Y3: Row Labels | Z3: Sum of Total Hc | AB3: =MAX(Z:Z) -> 256
A4: Hoang Ha Quyen NGUYEN | B4: Yes, count me in! | C4: 077300001719 | D4: 0968963049 | E4: No | G4: I’ll take the company bus | I4: Amaris Consulting | J4: Consultants | K4: HO Nguyen Hong Uyen | L4: In | M4: No | N4: 0 | O4: 0 | P4: 0 | Q4: 1 | R4: 1 | S4: 2 | Y4: 1 | Z4: 2 | AC4: =Z4 -> 2
A5: Thien Trang DOAN | B5: Yes, count me in! | C5: 091300011455 | D5: 0918626459 | E5: No | G5: I’ll take the company bus | H5: If there’s a single room, I wanna stay alone (if any) | I5: Amaris Consulting | J5: Consultants | K5: HO Nguyen Hong Uyen | L5: In | M5: No | N5: 0 | O5: 0 | P5: 0 | Q5: 1 | R5: 1 | S5: 2 | Y5: 2 | Z5: 2 | AC5: =Z5 -> 2
A6: Minh Thuan LE | B6: Yes, count me in! | C6: 086099002987 | D6: 0968933873 | E6: No | G6: I’ll take the company bus | I6: Amaris Consulting | J6: Consultants | K6: HA Phuong Thao | L6: In | M6: No | N6: 0 | O6: 0 | P6: 0 | Q6: 1 | R6: 1 | S6: 3 | Y6: 3 | Z6: 2 | AC6: =Z6 -> 2
A7: Van Thanh Thuan NGUYEN | B7: Yes, count me in! | C7: 080095004933 | D7: 0793485644 | E7: No | G7: I’ll take the company bus | H7: I'd like to request to be booked in the same room as the IVB team. | I7: Amaris Consulting | J7: Consultants | K7: HA Phuong Thao | L7: In | M7: No | N7: 0 | O7: 0 | P7: 0 | Q7: 1 | R7: 1 | S7: 3 | Y7: 4 | Z7: 2 | AC7: =Z7 -> 2
A8: Duc Minh CAO | B8: Yes, count me in! | C8: 080202010719 | D8: 0942198738 | E8: No | G8: I’ll take the company bus | I8: Amaris Consulting | J8: Consultants | K8: HA Phuong Thao | L8: In | M8: No | N8: 0 | O8: 0 | P8: 0 | Q8: 1 | R8: 1 | S8: 4 | Y8: 5 | Z8: 2 | AC8: =Z8 -> 2
A9: Hoang Tu LA | B9: Yes, count me in! | C9: 083097005277 | D9: 0386788883 | E9: No | G9: I’ll take the company bus | I9: Amaris Consulting | J9: Consultants | K9: HA Phuong Thao | L9: In | M9: No | N9: 0 | O9: 0 | P9: 0 | Q9: 1 | R9: 1 | S9: 4 | Y9: 6 | Z9: 2 | AC9: =Z9 -> 2
A10: Trung Nghia CAO | B10: Yes, count me in! | C10: 051094000961 | D10: 0938945445 | E10: No | G10: I’ll take the company bus | I10: Amaris Consulting | J10: Consultants | K10: HA Phuong Thao | L10: In | M10: No | N10: 0 | O10: 0 | P10: 0 | Q10: 1 | R10: 1 | S10: 5 | Y10: 7 | Z10: 2 | AC10: =Z10 -> 2
A11: Van Do TRAN | B11: Yes, count me in! | C11: 089097020361 | D11: 0967513840 | E11: No | G11: I’ll take the company bus | I11: Amaris Consulting | J11: Consultants | K11: HA Phuong Thao | L11: In | M11: No | N11: 0 | O11: 0 | P11: 0 | Q11: 1 | R11: 1 | S11: 5 | Y11: 8 | Z11: 2 | AC11: =Z11 -> 2
A12: Quang Trinh HA | B12: Yes, count me in! | C12: 087099016549 | D12: 0826759579 | E12: No | G12: I’ll take the company bus | I12: Amaris Consulting | J12: Consultants | K12: HA Phuong Thao | L12: In | M12: No | N12: 0 | O12: 0 | P12: 0 | Q12: 1 | R12: 1 | S12: 6 | Y12: 9 | Z12: 2 | AC12: =Z12 -> 2
A13: Binh Nam MAI | B13: Yes, count me in! | C13: 044099000541 | D13: 0948527910 | E13: No | G13: I’ll take the company bus | I13: Amaris Consulting | J13: Consultants | K13: HA Phuong Thao | L13: In | M13: No | N13: 0 | O13: 0 | P13: 0 | Q13: 1 | R13: 1 | S13: 6 | Y13: 10 | Z13: 2 | AC13: =Z13 -> 2
A14: Ngô Tấn Thành | B14: Yes, count me in! | C14: 089200015516 | D14: +84 329 382 782 | E14: No | G14: I’ll take the company bus | H14: Team chị My | I14: Amaris Consulting | J14: Consultants | K14: HA Phuong Thao | L14: In | M14: No | N14: 0 | O14: 0 | P14: 0 | Q14: 1 | R14: 1 | S14: 7 | Y14: 11 | Z14: 2 | AC14: =Z14 -> 2
A15: Hong Chuong NGUYEN | B15: Yes, count me in! | C15: 083084008265 | D15: 0989600669 | E15: No | G15: I’ll take the company bus | I15: Amaris Consulting | J15: Consultants | K15: HA Phuong Thao | L15: In | M15: No | N15: 0 | O15: 0 | P15: 0 | Q15: 1 | R15: 1 | S15: 7 | Y15: 12 | Z15: 2 | AC15: =Z15 -> 2
A16: Nguyễn Lê Thành | B16: Yes, count me in! | C16: 062201003205 | D16: +84 931 182 688 | E16: No | G16: I’ll take the company bus | I16: Amaris Consulting | J16: Consultants | K16: HA Phuong Thao | L16: In | M16: No | N16: 0 | O16: 0 | P16: 0 | Q16: 1 | R16: 1 | S16: 8 | Y16: 13 | Z16: 2 | AC16: =Z16 -> 2
A17: Ngoc Tuan NGUYEN | B17: Yes, count me in! | C17: 051099011537 | D17: 0973724249 | E17: No | G17: I’ll take the company bus | I17: Amaris Consulting | J17: Consultants | K17: HO Nguyen Hong Uyen | L17: In | M17: No | N17: 0 | O17: 0 | P17: 0 | Q17: 1 | R17: 1 | S17: 8 | Y17: 14 | Z17: 2 | AC17: =Z17 -> 2
A18: Thanh Nhan PHAN | B18: Yes, count me in! | C18: 079096015213 | D18: 0392357076 | E18: No | G18: I’ll take the company bus | I18: Amaris Consulting | J18: Consultants | K18: HO Nguyen Hong Uyen | L18: In | M18: No | N18: 0 | O18: 0 | P18: 0 | Q18: 1 | R18: 1 | S18: 9 | Y18: 15 | Z18: 2 | AC18: =Z18 -> 2
A19: Xuan Dat HOANG | B19: Yes, count me in! | C19: 066201016152 | D19: 0393688714 | E19: No | G19: I’ll take the company bus | I19: Amaris Consulting | J19: Consultants | K19: HO Nguyen Hong Uyen | L19: In | M19: No | N19: 0 | O19: 0 | P19: 0 | Q19: 1 | R19: 1 | S19: 9 | Y19: 16 | Z19: 2 | AC19: =Z19 -> 2
A20: Hong Son DAO | B20: Yes, count me in! | C20: 075200024308 | D20: 0938316793 | E20: No | G20: I’ll take the company bus | I20: Amaris Consulting | J20: Consultants | K20: HO Nguyen Hong Uyen | L20: In | M20: No | N20: 0 | O20: 0 | P20: 0 | Q20: 1 | R20: 1 | S20: 10 | Y20: 17 | Z20: 2 | AC20: =Z20 -> 2
A21: Thanh Son NGUYEN | B21: Yes, count me in! | C21: 051098005098 | D21: 0392497315 | E21: No | G21: I’ll take the company bus | I21: Amaris Consulting | J21: Consultants | K21: HO Nguyen Hong Uyen | L21: In | M21: No | N21: 0 | O21: 0 | P21: 0 | Q21: 1 | R21: 1 | S21: 10 | Y21: 18 | Z21: 2 | AC21: =Z21 -> 2
A22: Thanh Phuoc LE | B22: Yes, count me in! | C22: 068096007001 | D22: 0357556867 | E22: No | G22: I’ll take the company bus | I22: Amaris Consulting | J22: Consultants | K22: HO Nguyen Hong Uyen | L22: In | M22: No | N22: 0 | O22: 0 | P22: 0 | Q22: 1 | R22: 1 | S22: 11 | Y22: 19 | Z22: 2 | AC22: =Z22 -> 2
A23: Le Man Dat NGUYEN | B23: Yes, count me in! | C23: 086200001291 | D23: 0337804259 | E23: No | G23: I’ll take the company bus | I23: Amaris Consulting | J23: Consultants | K23: HO Nguyen Hong Uyen | L23: In | M23: No | N23: 0 | O23: 0 | P23: 0 | Q23: 1 | R23: 1 | S23: 11 | Y23: 20 | Z23: 2 | AC23: =Z23 -> 2
A24: Thanh Loc NGUYEN | B24: Yes, count me in! | C24: 046097000064 | D24: 0333515756 | E24: No | G24: I’ll take the company bus | I24: Amaris Consulting | J24: Consultants | K24: HO Nguyen Hong Uyen | L24: In | M24: No | N24: 0 | O24: 0 | P24: 0 | Q24: 1 | R24: 1 | S24: 12 | Y24: 21 | Z24: 2 | AC24: =Z24 -> 2
A25: Van Thanh Danh KHUAT | B25: Yes, count me in! | C25: 077203004018 | D25: 0971007831 | E25: No | G25: I’ll take the company bus | I25: Amaris Consulting | J25: Consultants | K25: HO Nguyen Hong Uyen | L25: In | M25: No | N25: 0 | O25: 0 | P25: 0 | Q25: 1 | R25: 1 | S25: 12 | Y25: 22 | Z25: 2 | AC25: =Z25 -> 2
A26: Huu Vinh NGUYEN | B26: Yes, count me in! | C26: 089200019968 | D26: 0974086701 | E26: No | G26: I’ll take the company bus | I26: Amaris Consulting | J26: Consultants | K26: HO Nguyen Hong Uyen | L26: In | M26: No | N26: 0 | O26: 0 | P26: 0 | Q26: 1 | R26: 1 | S26: 13 | Y26: 23 | Z26: 2 | AC26: =Z26 -> 2
... A30: Quang Nien NGUYEN | B30: Yes, count me in! | C30: 058201000239 | D30: 0855586358 | E30: No | G30: I’ll take the company bus | I30: Amaris Consulting | J30: Consultants | K30: HO Nguyen Hong Uyen | L30: In | M30: No | N30: 0 | O30: 0 | P30: 0 | Q30: 1 | R30: 1 | S30: 15 | Y30: 27 | Z30: 2 | AC30: =Z30 -> 2
A31: Cong Danh BUI | B31: Yes, count me in! | C31: 079201014939 | D31: 0902891404 | E31: No | G31: I’ll take the company bus | H31: Motion sickness pills | I31: Amaris Consulting | J31: Consultants | K31: NGUYEN Tien Nam | L31: In | M31: No | N31: 0 | O31: 0 | P31: 0 | Q31: 1 | R31: 1 | S31: 15 | Y31: 28 | Z31: 2 | AC31: =Z31 -> 2
A32: Huynh Chi Tin VO | B32: Yes, count me in! | C32: 079095022758 | D32: 0777104166 | E32: No | G32: I’ll take the company bus | I32: Amaris Consulting | J32: Consultants | K32: NGUYEN Tien Nam | L32: In | M32: No | N32: 0 | O32: 0 | P32: 0 | Q32: 1 | R32: 1 | S32: 16 | Y32: 29 | Z32: 2 | AC32: =Z32 -> 2
A33: Quang Trung DO | B33: Yes, count me in! | C33: 064200012749 | D33: 0396402696 | E33: No | G33: I’ll take the company bus | I33: Amaris Consulting | J33: Consultants | K33: NGUYEN Tien Nam | L33: In | M33: No | N33: 0 | O33: 0 | P33: 0 | Q33: 1 | R33: 1 | S33: 16 | Y33: 30 | Z33: 2 | AC33: =Z33 -> 2
A34: Thanh Tai NGUYEN | B34: Yes, count me in! | C34: 051090016586 | D34: 0988383049 | E34: Yes | F34: 1. Nguyen Thu Huyen - Female - 1991 - TBD 2. Nguyen Kha Han - Female - 2017 - TBD | G34: I’ll take the company bus | I34: Amaris Consulting | J34: Consultants | K34: HO Nguyen Hong Uyen | L34: In | M34: Yes | N34: 1 | O34: 1 | P34: 2 | Q34: 3 | R34: 1 | S34: 73 | Y34: 31 | Z34: 2 | AC34: =Z34 -> 2
A35: Nguyen Hong Uyen HO | B35: Yes, count me in! | C35: 079197003545 | D35: 0901936418 | E35: No | G35: I’ll take the company bus | I35: Amaris Consulting | J35: Managers | K35: NGUYEN Thai Ly | L35: In | M35: No | N35: 0 | O35: 0 | P35: 0 | Q35: 1 | R35: 1 | S35: 85 | Y35: 32 | Z35: 2 | AC35: =Z35 -> 2
A36: Phuong Thao HA | B36: Yes, count me in! | C36: 079197023976 | D36: 0909324150 | E36: No | G36: I’ll take the company bus | I36: Amaris Consulting | J36: Managers | K36: NGUYEN Thai Ly | L36: In | M36: No | N36: 0 | O36: 0 | P36: 0 | Q36: 1 | R36: 1 | S36: 88 | Y36: 33 | Z36: 2 | AC36: =Z36 -> 2
A37: Thanh Hang VU | B37: Yes, count me in! | C37: 001188049157 | D37: 0901401929 | E37: No | G37: I’ll take the company bus | I37: Amaris Consulting | J37: Directors | K37: THEVELIN Chloe | L37: In | M37: No | N37: 0 | O37: 0 | P37: 0 | Q37: 1 | R37: 1 | S37: 85 | Y37: 34 | Z37: 2 | AC37: =Z37 -> 2
A38: NGUYEN Tien Nam | B38: Yes, count me in! | C38: 077097008033 | D38: 0979040971 | E38: No | G38: I’ll take the company bus | I38: Amaris Consulting | J38: Managers | K38: NGUYEN Thai Ly | L38: In | M38: No | N38: 0 | O38: 0 | P38: 0 | Q38: 1 | R38: 1 | S38: 90 | Y38: 35 | Z38: 2 | AC38: =Z38 -> 2
A39: Cong Khanh HUYNH | B39: Yes, count me in! | C39: 087201004021 | D39: 0777905219 | E39: No | G39: I’ll take the company bus | I39: Amaris Consulting | J39: Consultants | K39: HUYNH Chi Cuong | L39: In | M39: No | N39: 0 | O39: 0 | P39: 0 | Q39: 1 | R39: 2 | S39: 17 | Y39: 36 | Z39: 2 | AC39: =Z39 -> 2
A40: Ngoc Thanh PHAM | B40: Yes, count me in! | C40: 060094011465 | D40: 0333950268 | E40: No | G40: I’ll take the company bus | I40: Amaris Consulting | J40: Consultants | K40: HUYNH Chi Cuong | L40: In | M40: No | N40: 0 | O40: 0 | P40: 0 | Q40: 1 | R40: 2 | S40: 20 | Y40: 37 | Z40: 2 | AC40: =Z40 -> 2
A41: Xuan Vu TRAN | B41: Yes, count me in! | C41: 046098001181 | D41: 0327360123 | E41: No | G41: I’ll take the company bus | I41: Amaris Consulting | J41: Consultants | K41: HUYNH Chi Cuong | L41: In | M41: No | N41: 0 | O41: 0 | P41: 0 | Q41: 1 | R41: 2 | S41: 20 | Y41: 38 | Z41: 2 | AC41: =Z41 -> 2
A42: Duy Nguyen VO NGOC | B42: Yes, count me in! | C42: 079201007186 | D42: 0919990145 | E42: No | G42: I’ll take the company bus | I42: Amaris Consulting | J42: Consultants | K42: LA Thuy My Hao | L42: In | M42: No | N42: 0 | O42: 0 | P42: 0 | Q42: 1 | R42: 2 | S42: 17 | Y42: 39 | Z42: 2 | AC42: =Z42 -> 2
A43: Chi Hau NGUYEN | B43: Yes, count me in! | C43: 086203010658 | D43: 0799549878 | E43: No | G43: I’ll take the company bus | I43: Amaris Consulting | J43: Consultants | K43: LA Thuy My Hao | L43: In | M43: No | N43: 0 | O43: 0 | P43: 0 | Q43: 1 | R43: 2 | S43: 18 | Y43: 40 | Z43: 2 | AC43: =Z43 -> 2
...

Sheet Bus
A1: Are you planning to join the company trip? | B1: Yes, count me in! | O1: Gia đình | Q1: 1 xe 45 người | AE1: Are you planning to join the company trip? | AF1: Yes, count me in!
O2: Count
A3: How do you plan to travel to the trip location? | B3: Bus No. | C3: Gov | D3: Dep | E3: N+1 | F3: Name | G3: Sum of C Fam | H3: Sum of A Fam | I3: Sum of Total Hc | J3: Bus No. | K3: Room No, | L3: With Fam | O3: Bus | P3: Current | Q3: Remaining | R3: Note | S3: Bus Leader | T3: Leader Mail | V3: Cong Danh BUI | W3: 902891404 | AE3: Gender | AF3: With Fam | AG3: Room No. | AH3: Gov | AI3: Dep | AJ3: N+1 | AK3: Email | AL3: Name | AM3: Sum of C Fam | AN3: Sum of A Fam | AO3: Sum of Fam Q | AP3: Sum of Total Hc
A4: I’ll arrange my own transportation | B4: (blank) | G4: 1 | H4: 2 | I4: 13 | L4: =IF(E4="",0,IF(I4=1,0.5,1)) -> 0 | O4: 1 | P4: =SUMIFS(I:I,B:B,Table5[[#This Row],[Bus]]) -> 38 | Q4: =45-Table5[[#This Row],[Current]] -> 7 | R4: Uyên + Thảo + | S4: Cong Danh BUI | U4: 1 | V4: congdanh.bui@amaris.com | W4: Cong Danh BUI | X4: 902891404 | AE4: Female | AF4: No | AG4: 1 | AH4: Amaris Consulting | AI4: Consultants | AJ4: HO Nguyen Hong Uyen | AK4: thuytien.phamdo@amaris.com | AL4: Do Thuy Tien PHAM | AM4: 0 | AN4: 0 | AO4: 0 | AP4: 1
A5: I’ll arrange my own transportation Total | G5: 1 | H5: 2 | I5: 13 | L5: =IF(E5="",0,IF(I5=1,0.5,1)) -> 0 | O5: 2 | P5: =SUMIFS(I:I,B:B,Table5[[#This Row],[Bus]]) -> 37 | Q5: =45-Table5[[#This Row],[Current]] -> 8 | R5: Hoang Thien + Huynh Chi cuong + Hao la | S5: Thuy My Hao LA | U5: 2 | V5: hla@amaris.com | W5: Thuy My Hao LA | X5: 375225989 | AE5: Female | AF5: No | AG5: 1 | AH5: Amaris Consulting | AI5: Consultants | AJ5: TRAN Thi Ha My | AK5: khanhgia.chung@amaris.com | AL5: Khanh Gia CHUNG | AM5: 0 | AN5: 0 | AO5: 0 | AP5: 1
A6: I’ll take the company bus | B6: 1 | G6: 1 | H6: 1 | I6: 38 | L6: =IF(E6="",0,IF(I6=1,0.5,1)) -> 0 | O6: 3 | P6: =SUMIFS(I:I,B:B,Table5[[#This Row],[Bus]]) -> 38 | Q6: =45-Table5[[#This Row],[Current]] -> 7 | R6: Nguyen Hoang Tuan Anh + Tran Thi Ha My (1/2) | S6: Van Hieu NGUYEN | U6: 3 | V6: vanhieu.nguyen@amaris.com | W6: Van Hieu NGUYEN | X6: 397459642 | AE6: Female | AF6: No | AG6: 2 | AH6: Amaris Consulting | AI6: Consultants | AJ6: HO Nguyen Hong Uyen | AK6: hoangha.nguyen@amaris.com | AL6: Hoang Ha Quyen NGUYEN | AM6: 0 | AN6: 0 | AO6: 0 | AP6: 1
A7: I’ll take the company bus | B7: 2 | G7: 0 | H7: 0 | I7: 37 | L7: =IF(E7="",0,IF(I7=1,0.5,1)) -> 0 | O7: 4 | P7: =SUMIFS(I:I,B:B,Table5[[#This Row],[Bus]]) -> 37 | Q7: =45-Table5[[#This Row],[Current]] -> 8 | R7: Nguyen Thi Minh Phuong + Tran Thi Ha My + ACT + Hiếu | S7: Thi Minh Phuong NGUYEN | U7: 4 | V7: pnguyen4@amaris.com | W7: Thi Minh Phuong NGUYEN | X7: 945745944 | AE7: Female | AF7: No | AG7: 2 | AH7: Amaris Consulting | AI7: Consultants | AJ7: HO Nguyen Hong Uyen | AK7: thientrang.doan@amaris.com | AL7: Thien Trang DOAN | AM7: 0 | AN7: 0 | AO7: 0 | AP7: 1
A8: I’ll take the company bus | B8: 3 | G8: 5 | H8: 6 | I8: 38 | L8: =IF(E8="",0,IF(I8=1,0.5,1)) -> 0 | O8: 5 | P8: =SUMIFS(I:I,B:B,Table5[[#This Row],[Bus]]) -> 31 | Q8: =45-Table5[[#This Row],[Current]] -> 14 | R8: Finance + CA | S8: Trung Kien NGUYEN | U8: 5 | V8: knguyen8@mantu.com | W8: Trung Kien NGUYEN | X8: 355327017 | AE8: Female | AF8: No | AG8: 31 | AH8: Amaris Consulting | AI8: Consultants | AJ8: HUYNH Chi Cuong | AK8: thithanh.le@amaris.com | AL8: Thi Thanh Huong LE | AM8: 0 | AN8: 0 | AO8: 0 | AP8: 1
A9: I’ll take the company bus | B9: 4 | G9: 0 | H9: 2 | I9: 37 | L9: =IF(E9="",0,IF(I9=1,0.5,1)) -> 0 | O9: 6 | P9: =SUMIFS(I:I,B:B,Table5[[#This Row],[Bus]]) -> 37 | Q9: =45-Table5[[#This Row],[Current]] -> 8 | R9: IT | S9: NGO Trinh Quynh Nhu | U9: 6 | V9: tngo@mantu.com | W9: NGO Trinh Quynh Nhu | X9: 886311686 | AE9: Female | AF9: No | AG9: 31 | AH9: Amaris Consulting | AI9: Consultants | AJ9: LA Thuy My Hao | AK9: phuonghang.lethi@amaris.com | AL9: Phuong Hang LE THI | AM9: 0 | AN9: 0 | AO9: 0 | AP9: 1
A10: I’ll take the company bus | B10: 5 | G10: 0 | H10: 1 | I10: 31 | L10: =IF(E10="",0,IF(I10=1,0.5,1)) -> 0 | O10: 7 | P10: =SUMIFS(I:I,B:B,Table5[[#This Row],[Bus]]) -> 29 | Q10: =45-Table5[[#This Row],[Current]] -> 16 | R10: Xe chờ + Hảo + Ly + HR | S10: Ngoc Quoc TRAN | U10: 7 | V10: tran.ngocquoc@amaris.com | W10: Ngoc Quoc TRAN | X10: 799010869 | AE10: Female | AF10: No | AG10: 32 | AH10: Amaris Consulting | AI10: Consultants | AJ10: LA Thuy My Hao | AK10: ngocmy.ha@amaris.com | AL10: Ngoc My HA | AM10: 0 | AN10: 0 | AO10: 0 | AP10: 1
A11: I’ll take the company bus | B11: 6 | G11: 1 | H11: 1 | I11: 37 | L11: =IF(E11="",0,IF(I11=1,0.5,1)) -> 0 | O11: 8 | P11: =SUMIFS(I:I,B:B,Table5[[#This Row],[Bus]]) -> 34 | Q11: =45-Table5[[#This Row],[Current]] -> 11 | R11: R-Team + Thomas Buc | S11: Diem Thien Nga - Micky HUYNH | U11: 8 | V11: nhuynh@mantu.com | W11: Diem Thien Nga - Micky HUYNH | X11: 763889811 | AE11: Female | AF11: No | AG11: 32 | AH11: Amaris Consulting | AI11: Consultants | AJ11: LA Thuy My Hao | AK11: tramngan.tranthi@amaris.com | AL11: Thi Tram Ngan TRAN | AM11: 0 | AN11: 0 | AO11: 0 | AP11: 1
A12: I’ll take the company bus | B12: 7 | G12: 0 | H12: 0 | I12: 29 | L12: =IF(E12="",0,IF(I12=1,0.5,1)) -> 0 | AE12: Female | AF12: No | AG12: 33 | AH12: Amaris Consulting | AI12: Consultants | AJ12: LA Thuy My Hao | AK12: ngocthuy.pham@amaris.com | AL12: Ngoc Thuy Trang PHAM | AM12: 0 | AN12: 0 | AO12: 0 | AP12: 1
A13: I’ll take the company bus | B13: 8 | C13: ACT | D13: ACT Sales & Pre-sales | E13: MAVANI Amit | F13: Kieu Anh HOANG | G13: 0 | H13: 0 | I13: 1 | L13: =IF(E13="",0,IF(I13=1,0.5,1)) -> 0.5 | AE13: Female | AF13: No | AG13: 33 | AH13: Amaris Consulting | AI13: Consultants | AJ13: LA Thuy My Hao | AK13: thaian.phamthuy@amaris.com | AL13: Thai An PHAM THUY | AM13: 0 | AN13: 0 | AO13: 0 | AP13: 1
A14: I’ll take the company bus | B14: 8 | C14: ACT | D14: ACT Sales & Pre-sales | E14: MAVANI Amit | F14: Triet HUYNH MINH | G14: 0 | H14: 0 | I14: 1 | L14: =IF(E14="",0,IF(I14=1,0.5,1)) -> 0.5 | AE14: Female | AF14: No | AG14: 34 | AH14: Amaris Consulting | AI14: Consultants | AJ14: LA Thuy My Hao | AK14: ngoctran.tathi@amaris.com | AL14: Ngoc Tran TA THI | AM14: 0 | AN14: 0 | AO14: 0 | AP14: 1
A15: I’ll take the company bus | B15: 8 | C15: Administrative & Finance | D15: Operational Finance | E15: DE LACOMBE Romain | F15: Geoffrey DUTERTRE | G15: 0 | H15: 0 | I15: 1 | L15: =IF(E15="",0,IF(I15=1,0.5,1)) -> 0.5 | R15: To update | AE15: Female | AF15: No | AG15: 34 | AH15: Amaris Consulting | AI15: Consultants | AJ15: LA Thuy My Hao | AK15: tuuyen.dinhthi@amaris.com | AL15: Tu Uyen DINH THI | AM15: 0 | AN15: 0 | AO15: 0 | AP15: 1
A16: I’ll take the company bus | B16: 8 | C16: Amaris Consulting | D16: Consultants | E16: VETTUKAD Amit | F16: Phuong Thao NGUYEN | G16: 0 | H16: 0 | I16: 1 | L16: =IF(E16="",0,IF(I16=1,0.5,1)) -> 0.5 | R16: Thai Ly + Tien Nam | S16: 2 Trang + c Phương + a Hoang | AE16: Female | AF16: No | AG16: 44 | AH16: Amaris Consulting | AI16: Consultants | AJ16: TRAN Thi Ha My | AK16: thiviet.nguyen@amaris.com | AL16: Thi Viet Trinh NGUYEN | AM16: 0 | AN16: 0 | AO16: 0 | AP16: 1
A17: I’ll take the company bus | B17: 8 | C17: Amaris Consulting | D17: Consulting Talent Acquisition | E17: GUILLOTON Eve | F17: Ho Khanh Vy NGUYEN | G17: 0 | H17: 0 | I17: 1 | L17: =IF(E17="",0,IF(I17=1,0.5,1)) -> 0.5 | R17: Ha MY + Thao + Uyen | AE17: Female | AF17: No | AG17: 44 | AH17: Amaris Consulting | AI17: Consultants | AJ17: TRAN Thi Ha My | AK17: tranthuy.lu@amaris.com | AL17: Tran Thuy Linh LU | AM17: 0 | AN17: 0 | AO17: 0 | AP17: 1
A18: I’ll take the company bus | B18: 8 | C18: Amaris Consulting | D18: Consulting Talent Acquisition | E18: HONG Nguyen Tu Nhi | F18: Thi Anh Thu TRAN | G18: 0 | H18: 0 | I18: 1 | L18: =IF(E18="",0,IF(I18=1,0.5,1)) -> 0.5 | R18: Hoang Thien + Huynh Chi cuong + Hao la + Tuan Anh | AE18: Female | AF18: No | AG18: 45 | AH18: Amaris Consulting | AI18: Consultants | AJ18: HA Phuong Thao | AK18: phamkhanh.tran@amaris.com | AL18: Pham Khanh Linh TRAN | AM18: 0 | AN18: 0 | AO18: 0 | AP18: 1
A19: I’ll take the company bus | B19: 8 | C19: Amaris Consulting | D19: Consulting Talent Acquisition | E19: NGUYEN Ho Khanh Vy | F19: Dang Thuy Duong NGUYEN | G19: 0 | H19: 0 | I19: 1 | L19: =IF(E19="",0,IF(I19=1,0.5,1)) -> 0.5 | R19: Duc Quy + Minh Phương | AE19: Female | AF19: No | AG19: 45 | AH19: Amaris Consulting | AI19: Consultants | AJ19: NGUYEN Hoang Tuan Anh | AK19: thinguyet.nong@amaris.com | AL19: Thi Nguyet NONG | AM19: 0 | AN19: 0 | AO19: 0 | AP19: 1
A20: I’ll take the company bus | B20: 8 | C20: Amaris Consulting | D20: Consulting Talent Acquisition | E20: NGUYEN Ho Khanh Vy | F20: Hoang Bich Tran NGUYEN | G20: 0 | H20: 1 | I20: 2 | L20: =IF(E20="",0,IF(I20=1,0.5,1)) -> 1 | AE20: Female | AF20: No | AG20: 60 | AH20: Amaris Consulting | AI20: Consultants | AJ20: NGUYEN Thai Ly | AK20: kimanh.do@amaris.com | AL20: Kim Anh DO | AM20: 0 | AN20: 0 | AO20: 0 | AP20: 1
A21: I’ll take the company bus | B21: 8 | C21: Amaris Consulting | D21: Consulting Talent Acquisition | E21: NGUYEN Ho Khanh Vy | F21: Nguyen Tu Nhi HONG | G21: 0 | H21: 0 | I21: 1 | L21: =IF(E21="",0,IF(I21=1,0.5,1)) -> 0.5 | AE21: Female | AF21: No | AG21: 60 | AH21: Amaris Consulting | AI21: Consultants | AJ21: NGUYEN Thi Minh Phuong | AK21: phuong.nguyenthiquynh@amaris.com | AL21: Thi Quynh Phuong NGUYEN | AM21: 0 | AN21: 0 | AO21: 0 | AP21: 1
A22: I’ll take the company bus | B22: 8 | C22: Amaris Consulting | D22: Consulting Talent Acquisition | E22: NGUYEN Ho Khanh Vy | F22: Thai An PHAM | G22: 0 | H22: 1 | I22: 2 | L22: =IF(E22="",0,IF(I22=1,0.5,1)) -> 1 | AE22: Female | AF22: No | AG22: 61 | AH22: Amaris Consulting | AI22: Consultants | AJ22: TRAN Thi Ha My | AK22: qtran5@amaris.com | AL22: Trần Quỳnh Anh | AM22: 0 | AN22: 0 | AO22: 0 | AP22: 1
A23: I’ll take the company bus | B23: 8 | C23: Amaris Consulting | D23: Consulting Talent Acquisition | E23: NGUYEN Hoang Bich Tran | F23: Hoang Dung LE | G23: 0 | H23: 0 | I23: 1 | L23: =IF(E23="",0,IF(I23=1,0.5,1)) -> 0.5 | O23: Bus | P23: Current | Q23: Remaining | R23: Note | AE23: Female | AF23: No | AG23: 61 | AH23: Amaris Consulting | AI23: Delivery | AJ23: NGUYEN The Trinh | AK23: my.tran@amaris.com | AL23: Thi Ha My TRAN | AM23: 0 | AN23: 0 | AO23: 0 | AP23: 1
A24: I’ll take the company bus | B24: 8 | C24: Amaris Consulting | D24: Consulting Talent Acquisition | E24: NGUYEN Hoang Bich Tran | F24: Le Khanh Chi PHAM | G24: 0 | H24: 0 | I24: 1 | L24: =IF(E24="",0,IF(I24=1,0.5,1)) -> 0.5 | O24: 1 | P24: =SUMIFS(I:I,B:B,Table5[[#This Row],[Bus]]) -> 0 | Q24: =45-Table5[[#This Row],[Current]] -> #VALUE! | R24: NGUYEN Thai Ly + HA Phuong Thao + HO Nguyen Hong Uyen + Nguyen Tien Nam | AE24: Female | AF24: No | AG24: 62 | AH24: Amaris Consulting | AI24: Consultants | AJ24: TRAN Thi Ha My | AK24: khanhlinh.dangngoc@amaris.com | AL24: Ngoc Khanh Linh DANG | AM24: 0 | AN24: 0 | AO24: 0 | AP24: 1
A25: I’ll take the company bus | B25: 8 | C25: Amaris Consulting | D25: Consulting Talent Acquisition | E25: NGUYEN Hoang Bich Tran | F25: Tran Thao Vy PHAM | G25: 0 | H25: 0 | I25: 1 | L25: =IF(E25="",0,IF(I25=1,0.5,1)) -> 0.5 | O25: 2 | P25: =SUMIFS(I:I,B:B,Table5[[#This Row],[Bus]]) -> 0 | Q25: =45-Table5[[#This Row],[Current]] -> #VALUE! | R25: Hoang Thien + Huynh Chi cuong + Hao la | AE25: Female | AF25: No | AG25: 62 | AH25: Amaris Consulting | AI25: Consultants | AJ25: TRAN Thi Ha My | AK25: thihue.do@amaris.com | AL25: Thi Hue DO | AM25: 0 | AN25: 0 | AO25: 0 | AP25: 1
A26: I’ll take the company bus | B26: 8 | C26: Amaris Consulting | D26: Consulting Talent Acquisition | E26: PHAM Thai An | F26: Hieu Minh DO | G26: 0 | H26: 0 | I26: 1 | L26: =IF(E26="",0,IF(I26=1,0.5,1)) -> 0.5 | O26: 3 | P26: =SUMIFS(I:I,B:B,Table5[[#This Row],[Bus]]) -> 0 | Q26: =45-Table5[[#This Row],[Current]] -> #VALUE! | R26: Nguyen Hoang Tuan Anh + Tran Thi Ha My (1/2) + Nguyen Tien Nam | AE26: Female | AF26: No | AG26: 68 | AH26: Amaris Consulting | AI26: Managers | AJ26: VU Thanh Hang | AK26: nly@amaris.com | AL26: Thai Ly NGUYEN | AM26: 0 | AN26: 0 | AO26: 0 | AP26: 1
A27: I’ll take the company bus | B27: 8 | C27: Amaris Consulting | D27: Delivery | E27: GALLOT Brice | F27: Trung Hieu NGUYEN | G27: 0 | H27: 0 | I27: 1 | L27: =IF(E27="",0,IF(I27=1,0.5,1)) -> 0.5 | O27: 4 | P27: =SUMIFS(I:I,B:B,Table5[[#This Row],[Bus]]) -> 0 | Q27: =45-Table5[[#This Row],[Current]] -> #VALUE! | R27: Nguyen Thi Minh Phuong + Tran Thi Ha My + Delivery | AE27: Female | AF27: No | AG27: 69 | AH27: Amaris Consulting | AI27: Consultants | AJ27: TRAN Thi Ha My | AK27: baongoc.nguyen@amaris.com | AL27: NGUYEN Bao Ngoc | AM27: 0 | AN27: 0 | AO27: 0 | AP27: 1
A28: I’ll take the company bus | B28: 8 | C28: Amaris Consulting | D28: Delivery | E28: NGUYEN Trung Hieu | F28: Tu NGUYEN ANH | G28: 0 | H28: 0 | I28: 1 | L28: =IF(E28="",0,IF(I28=1,0.5,1)) -> 0.5 | O28: 5 | P28: =SUMIFS(I:I,B:B,Table5[[#This Row],[Bus]]) -> 0 | Q28: =45-Table5[[#This Row],[Current]] -> #VALUE! | R28: Finance + CA | AE28: Female | AF28: No | AG28: 69 | AH28: Amaris Consulting | AI28: Consultants | AJ28: TRAN Thi Ha My | AK28: thikhanh.nguyen@amaris.com | AL28: Thi Khanh NGUYEN | AM28: 0 | AN28: 0 | AO28: 0 | AP28: 1
A29: I’ll take the company bus | B29: 8 | C29: Amaris Consulting | D29: Managers | E29: NGUYEN Thai Ly | F29: NGUYEN Tien Nam | G29: 0 | H29: 0 | I29: 1 | L29: =IF(E29="",0,IF(I29=1,0.5,1)) -> 0.5 | O29: 6 | P29: =SUMIFS(I:I,B:B,Table5[[#This Row],[Bus]]) -> 0 | Q29: =45-Table5[[#This Row],[Current]] -> #VALUE! | R29: IT | AE29: Female | AF29: No | AG29: 82 | AH29: Human Resources | AI29: Payroll Solutions | AJ29: COMAS Mireille | AK29: tle19@mantu.com | AL29: Thi My Tam - Cindy LE | AM29: 0 | AN29: 0 | AO29: 0 | AP29: 1
A30: I’ll take the company bus | B30: 8 | C30: Amaris Consulting | D30: Presales | E30: JOLLIOT Marie-Benoîte | F30: Arthur CAMARET | G30: 0 | H30: 0 | I30: 1 | L30: =IF(E30="",0,IF(I30=1,0.5,1)) -> 0.5 | O30: 7 | P30: =SUMIFS(I:I,B:B,Table5[[#This Row],[Bus]]) -> 0 | Q30: =45-Table5[[#This Row],[Current]] -> #VALUE! | R30: Xe chờ + Duc QUY | AE30: Female | AF30: No | AG30: 82 | AH30: Human Resources | AI30: People Operations | AJ30: NGUYEN Thuc Hao | AK30: nnguyen16@mantu.com | AL30: Le Kim Ngan NGUYEN | AM30: 0 | AN30: 0 | AO30: 0 | AP30: 1
A31: I’ll take the company bus | B31: 8 | C31: Amaris Consulting | D31: Presales | E31: CAMARET Arthur | F31: Clémence LIN | G31: 0 | H31: 0 | I31: 1 | L31: =IF(E31="",0,IF(I31=1,0.5,1)) -> 0.5 | O31: 8 | P31: =SUMIFS(I:I,B:B,Table5[[#This Row],[Bus]]) -> 0 | Q31: =45-Table5[[#This Row],[Current]] -> #VALUE! | R31: R-Team + Thomas Buc + Managers/Directors | AE31: Female | AF31: No | AG31: 83 | AH31: Human Resources | AI31: Compensation & Benefits | AJ31: CAP Kim Hoang | AK31: mdang1@mantu.com | AL31: Minh Thu DANG | AM31: 0 | AN31: 0 | AO31: 0 | AP31: 1
